<?xml version="1.0"?>
<robot name="visual">

<material name="blue">
    <color rgba="0 0 0.8 1"/>
  </material>
  <material name="black">
    <color rgba="0 0 0 1"/>
  </material>
  <material name="white">
    <color rgba="1 1 1 1"/>
  </material>

  <link name="base_link">
    <visual>
            <origin rpy="0.0 0 0" xyz="0 0 0"/>

      <geometry>
          <mesh filename="package://modularm/meshes/base_link.stl" scale="1 1 1"/>
      </geometry>
    </visual>
    <collision>
            <origin rpy="0.0 0 0" xyz="0 0 0"/>
      <geometry>
          <mesh filename="package://modularm/meshes/base_link.stl" scale="1 1 1"/>
      </geometry>
    </collision>

  </link>

<joint name="base_shaft" type="revolute">
  <parent link="parent_link" />
  <child link="child_link" />
  <origin xyz="0 0 0" rpy="0 0 0" />
  <axis xyz="1 0 0" />
  <limit lower="-1.0" upper="1.0" effort="100" velocity="100" />
</joint>

</robot>